Workbook

Sheet Geral
A1: Backlog do Produto — Priorização Consolidada
A2: A Média do Índice é calculada automaticamente a partir das avaliações individuais de cada membro. A Prioridade MoSCoW é atribuída com base nessa média.
A3: Código | B3: Item do Backlog | C3: RF | D3: Média do Índice | E3: Prioridade (MoSCoW)
A4: E01 | B4: Gestão de Conta e Perfil
A5: F01 | B5: Cadastro e Autenticação
A6: US01 | B6: Criar conta com nome, e-mail e senha | C6: RF01 | D6: =IFERROR(AVERAGE('André'!F6,Daniel!F6,Eduardo!F6,Eduardo!F6,Giovanni!F6,'João'!F6,'José'!F6,Lucas!F6,Samuel!F6,Mateus!F6),"") -> 2.75 | E6: =IF(D6="","",IF(D6>=2.5,"Must Have",IF(D6>=2,"Should Have",IF(D6>=0.5,"Could Have","Won't Have")))) -> Must Have
A7: US02 | B7: Realizar login com e-mail e senha | C7: RF02 | D7: =IFERROR(AVERAGE('André'!F7,Daniel!F7,Eduardo!F7,Eduardo!F7,Giovanni!F7,'João'!F7,'José'!F7,Lucas!F7,Samuel!F7,Mateus!F7),"") -> 3.1666667 | E7: =IF(D7="","",IF(D7>=2.5,"Must Have",IF(D7>=2,"Should Have",IF(D7>=0.5,"Could Have","Won't Have")))) -> Must Have
A8: US03 | B8: Encerrar acesso autenticado | C8: RF03 | D8: =IFERROR(AVERAGE('André'!F8,Daniel!F8,Eduardo!F8,Eduardo!F8,Giovanni!F8,'João'!F8,'José'!F8,Lucas!F8,Samuel!F8,Mateus!F8),"") -> 3.1666667 | E8: =IF(D8="","",IF(D8>=2.5,"Must Have",IF(D8>=2,"Should Have",IF(D8>=0.5,"Could Have","Won't Have")))) -> Must Have
A9: US04 | B9: Recuperar senha via e-mail | C9: RF04 | D9: =IFERROR(AVERAGE('André'!F9,Daniel!F9,Eduardo!F9,Eduardo!F9,Giovanni!F9,'João'!F9,'José'!F9,Lucas!F9,Samuel!F9,Mateus!F9),"") -> 0.85833333 | E9: =IF(D9="","",IF(D9>=2.5,"Must Have",IF(D9>=2,"Should Have",IF(D9>=0.5,"Could Have","Won't Have")))) -> Could Have
A10: F02 | B10: Gestão de Perfil
A11: US05 | B11: Visualizar perfil com dados e classificação | C11: RF05 | D11: =IFERROR(AVERAGE('André'!F11,Daniel!F11,Eduardo!F11,Eduardo!F11,Giovanni!F11,'João'!F11,'José'!F11,Lucas!F11,Samuel!F11,Mateus!F11),"") -> 1.5 | E11: =IF(D11="","",IF(D11>=2.5,"Must Have",IF(D11>=2,"Should Have",IF(D11>=0.5,"Could Have","Won't Have")))) -> Could Have
A12: US06 | B12: Editar nome e senha do perfil | C12: RF06 | D12: =IFERROR(AVERAGE('André'!F12,Daniel!F12,Eduardo!F12,Eduardo!F12,Giovanni!F12,'João'!F12,'José'!F12,Lucas!F12,Samuel!F12,Mateus!F12),"") -> 1.9444444 | E12: =IF(D12="","",IF(D12>=2.5,"Must Have",IF(D12>=2,"Should Have",IF(D12>=0.5,"Could Have","Won't Have")))) -> Could Have
A13: US07 | B13: Excluir conta permanentemente | C13: RF07 | D13: =IFERROR(AVERAGE('André'!F13,Daniel!F13,Eduardo!F13,Eduardo!F13,Giovanni!F13,'João'!F13,'José'!F13,Lucas!F13,Samuel!F13,Mateus!F13),"") -> 2.4166667 | E13: =IF(D13="","",IF(D13>=2.5,"Must Have",IF(D13>=2,"Should Have",IF(D13>=0.5,"Could Have","Won't Have")))) -> Should Have
A14: E02 | B14: Onboarding e Classificação
A15: F03 | B15: Questionário de Classificação
A16: US08 | B16: Responder questionário de classificação | C16: RF08 | D16: =IFERROR(AVERAGE('André'!F16,Daniel!F16,Eduardo!F16,Eduardo!F16,Giovanni!F16,'João'!F16,'José'!F16,Lucas!F16,Samuel!F16,Mateus!F16),"") -> 1.8333333 | E16: =IF(D16="","",IF(D16>=2.5,"Must Have",IF(D16>=2,"Should Have",IF(D16>=0.5,"Could Have","Won't Have")))) -> Could Have
A17: US09 | B17: Classificar perfil automaticamente | C17: RF09 | D17: =IFERROR(AVERAGE('André'!F17,Daniel!F17,Eduardo!F17,Eduardo!F17,Giovanni!F17,'João'!F17,'José'!F17,Lucas!F17,Samuel!F17,Mateus!F17),"") -> 1.3555556 | E17: =IF(D17="","",IF(D17>=2.5,"Must Have",IF(D17>=2,"Should Have",IF(D17>=0.5,"Could Have","Won't Have")))) -> Could Have
A18: US10 | B18: Refazer questionário de classificação | C18: RF12 | D18: =IFERROR(AVERAGE('André'!F18,Daniel!F18,Eduardo!F18,Eduardo!F18,Giovanni!F18,'João'!F18,'José'!F18,Lucas!F18,Samuel!F18,Mateus!F18),"") -> 1.5694444 | E18: =IF(D18="","",IF(D18>=2.5,"Must Have",IF(D18>=2,"Should Have",IF(D18>=0.5,"Could Have","Won't Have")))) -> Could Have
A19: F04 | B19: Sugestão de Treino Inicial
A20: US11 | B20: Visualizar sugestão de rotina por perfil | C20: RF10 | D20: =IFERROR(AVERAGE('André'!F20,Daniel!F20,Eduardo!F20,Eduardo!F20,Giovanni!F20,'João'!F20,'José'!F20,Lucas!F20,Samuel!F20,Mateus!F20),"") -> 1.5833333 | E20: =IF(D20="","",IF(D20>=2.5,"Must Have",IF(D20>=2,"Should Have",IF(D20>=0.5,"Could Have","Won't Have")))) -> Could Have
A21: US12 | B21: Recusar sugestão e prosseguir sem rotina | C21: RF11 | D21: =IFERROR(AVERAGE('André'!F21,Daniel!F21,Eduardo!F21,Eduardo!F21,Giovanni!F21,'João'!F21,'José'!F21,Lucas!F21,Samuel!F21,Mateus!F21),"") -> 2.6388889 | E21: =IF(D21="","",IF(D21>=2.5,"Must Have",IF(D21>=2,"Should Have",IF(D21>=0.5,"Could Have","Won't Have")))) -> Must Have
A22: E03 | B22: Planejamento de Treino
A23: F05 | B23: Gestão de Exercícios
A24: US13 | B24: Cadastrar exercício com nome e grupo muscular | C24: RF13 | D24: =IFERROR(AVERAGE('André'!F24,Daniel!F24,Eduardo!F24,Eduardo!F24,Giovanni!F24,'João'!F24,'José'!F24,Lucas!F24,Samuel!F24,Mateus!F24),"") -> 2.6111111 | E24: =IF(D24="","",IF(D24>=2.5,"Must Have",IF(D24>=2,"Should Have",IF(D24>=0.5,"Could Have","Won't Have")))) -> Must Have
A25: US14 | B25: Consultar exercícios por nome ou grupo | C25: RF14 | D25: =IFERROR(AVERAGE('André'!F25,Daniel!F25,Eduardo!F25,Eduardo!F25,Giovanni!F25,'João'!F25,'José'!F25,Lucas!F25,Samuel!F25,Mateus!F25),"") -> 2.6944444 | E25: =IF(D25="","",IF(D25>=2.5,"Must Have",IF(D25>=2,"Should Have",IF(D25>=0.5,"Could Have","Won't Have")))) -> Must Have
A26: US15 | B26: Editar exercício cadastrado | C26: RF15 | D26: =IFERROR(AVERAGE('André'!F26,Daniel!F26,Eduardo!F26,Eduardo!F26,Giovanni!F26,'João'!F26,'José'!F26,Lucas!F26,Samuel!F26,Mateus!F26),"") -> 2.25 | E26: =IF(D26="","",IF(D26>=2.5,"Must Have",IF(D26>=2,"Should Have",IF(D26>=0.5,"Could Have","Won't Have")))) -> Should Have
A27: US16 | B27: Inativar exercício não utilizado | C27: RF16 | D27: =IFERROR(AVERAGE('André'!F27,Daniel!F27,Eduardo!F27,Eduardo!F27,Giovanni!F27,'João'!F27,'José'!F27,Lucas!F27,Samuel!F27,Mateus!F27),"") -> 2.3888889 | E27: =IF(D27="","",IF(D27>=2.5,"Must Have",IF(D27>=2,"Should Have",IF(D27>=0.5,"Could Have","Won't Have")))) -> Should Have
A28: F06 | B28: Gestão de Rotinas
A29: US17 | B29: Criar rotina com divisões e parâmetros planejados | C29: RF17 | D29: =IFERROR(AVERAGE('André'!F29,Daniel!F29,Eduardo!F29,Eduardo!F29,Giovanni!F29,'João'!F29,'José'!F29,Lucas!F29,Samuel!F29,Mateus!F29),"") -> 2.0416667 | E29: =IF(D29="","",IF(D29>=2.5,"Must Have",IF(D29>=2,"Should Have",IF(D29>=0.5,"Could Have","Won't Have")))) -> Should Have
A30: US18 | B30: Consultar rotinas e identificar a ativa | C30: RF18 | D30: =IFERROR(AVERAGE('André'!F30,Daniel!F30,Eduardo!F30,Eduardo!F30,Giovanni!F30,'João'!F30,'José'!F30,Lucas!F30,Samuel!F30,Mateus!F30),"") -> 2.6944444 | E30: =IF(D30="","",IF(D30>=2.5,"Must Have",IF(D30>=2,"Should Have",IF(D30>=0.5,"Could Have","Won't Have")))) -> Must Have
A31: US19 | B31: Editar rotina existente | C31: RF19 | D31: =IFERROR(AVERAGE('André'!F31,Daniel!F31,Eduardo!F31,Eduardo!F31,Giovanni!F31,'João'!F31,'José'!F31,Lucas!F31,Samuel!F31,Mateus!F31),"") -> 2.0833333 | E31: =IF(D31="","",IF(D31>=2.5,"Must Have",IF(D31>=2,"Should Have",IF(D31>=0.5,"Could Have","Won't Have")))) -> Should Have
A32: US20 | B32: Inativar rotina não utilizada | C32: RF20 | D32: =IFERROR(AVERAGE('André'!F32,Daniel!F32,Eduardo!F32,Eduardo!F32,Giovanni!F32,'João'!F32,'José'!F32,Lucas!F32,Samuel!F32,Mateus!F32),"") -> 2.4722222 | E32: =IF(D32="","",IF(D32>=2.5,"Must Have",IF(D32>=2,"Should Have",IF(D32>=0.5,"Could Have","Won't Have")))) -> Should Have
A33: US21 | B33: Definir rotina como ativa | C33: RF21 | D33: =IFERROR(AVERAGE('André'!F33,Daniel!F33,Eduardo!F33,Eduardo!F33,Giovanni!F33,'João'!F33,'José'!F33,Lucas!F33,Samuel!F33,Mateus!F33),"") -> 2.6944444 | E33: =IF(D33="","",IF(D33>=2.5,"Must Have",IF(D33>=2,"Should Have",IF(D33>=0.5,"Could Have","Won't Have")))) -> Must Have
A34: E04 | B34: Execução e Registro
A35: F07 | B35: Registro de Sessão
A36: US22 | B36: Registrar sessão de treino com execução real | C36: RF22 | D36: =IFERROR(AVERAGE('André'!F36,Daniel!F36,Eduardo!F36,Eduardo!F36,Giovanni!F36,'João'!F36,'José'!F36,Lucas!F36,Samuel!F36,Mateus!F36),"") -> 1.6388889 | E36: =IF(D36="","",IF(D36>=2.5,"Must Have",IF(D36>=2,"Should Have",IF(D36>=0.5,"Could Have","Won't Have")))) -> Could Have
A37: US23 | B37: Consultar detalhes de uma sessão | C37: RF23 | D37: =IFERROR(AVERAGE('André'!F37,Daniel!F37,Eduardo!F37,Eduardo!F37,Giovanni!F37,'João'!F37,'José'!F37,Lucas!F37,Samuel!F37,Mateus!F37),"") -> 2.1944444 | E37: =IF(D37="","",IF(D37>=2.5,"Must Have",IF(D37>=2,"Should Have",IF(D37>=0.5,"Could Have","Won't Have")))) -> Should Have
A38: US24 | B38: Editar sessão para corrigir erros | C38: RF24 | D38: =IFERROR(AVERAGE('André'!F38,Daniel!F38,Eduardo!F38,Eduardo!F38,Giovanni!F38,'João'!F38,'José'!F38,Lucas!F38,Samuel!F38,Mateus!F38),"") -> 1.8611111 | E38: =IF(D38="","",IF(D38>=2.5,"Must Have",IF(D38>=2,"Should Have",IF(D38>=0.5,"Could Have","Won't Have")))) -> Could Have
A39: US25 | B39: Excluir sessão registrada | C39: RF25 | D39: =IFERROR(AVERAGE('André'!F39,Daniel!F39,Eduardo!F39,Eduardo!F39,Giovanni!F39,'João'!F39,'José'!F39,Lucas!F39,Samuel!F39,Mateus!F39),"") -> 3 | E39: =IF(D39="","",IF(D39>=2.5,"Must Have",IF(D39>=2,"Should Have",IF(D39>=0.5,"Could Have","Won't Have")))) -> Must Have
A40: E05 | B40: Acompanhamento e Evolução
...

Sheet André
A1: Priorização Individual — André Ricardo
A2: Complexidade: 1=Muito baixa, 2=Baixa, 3=Média, 4=Alta, 5=Muito alta | Impacto no Usuário: 1=Muito baixo, 2=Baixo, 3=Médio, 4=Alto, 5=Muito alto | Índice = Impacto / Complexidade
A3: Código | B3: Item do Backlog | C3: RF | D3: Complexidade (1-5) | E3: Impacto no Usuário (1-5) | F3: Índice de Prioridade
A4: E01 | B4: Gestão de Conta e Perfil
A5: F01 | B5: Cadastro e Autenticação
A6: US01 | B6: Criar conta com nome, e-mail e senha | C6: RF01 | D6: 2 | E6: 3 | F6: =IF(AND(D6<>"",E6<>""),E6/D6,"") -> 1.5
A7: US02 | B7: Realizar login com e-mail e senha | C7: RF02 | D7: 2 | E7: 3 | F7: =IF(AND(D7<>"",E7<>""),E7/D7,"") -> 1.5
A8: US03 | B8: Encerrar acesso autenticado | C8: RF03 | D8: 1 | E8: 3 | F8: =IF(AND(D8<>"",E8<>""),E8/D8,"") -> 3
A9: US04 | B9: Recuperar senha via e-mail | C9: RF04 | D9: 5 | E9: 3 | F9: =IF(AND(D9<>"",E9<>""),E9/D9,"") -> 0.6
A10: F02 | B10: Gestão de Perfil
A11: US05 | B11: Visualizar perfil com dados e classificação | C11: RF05 | D11: 2 | E11: 4 | F11: =IF(AND(D11<>"",E11<>""),E11/D11,"") -> 2
A12: US06 | B12: Editar nome e senha do perfil | C12: RF06 | D12: 3 | E12: 4 | F12: =IF(AND(D12<>"",E12<>""),E12/D12,"") -> 1.3333333
A13: US07 | B13: Excluir conta permanentemente | C13: RF07 | D13: 1 | E13: 3 | F13: =IF(AND(D13<>"",E13<>""),E13/D13,"") -> 3
A14: E02 | B14: Onboarding e Classificação
A15: F03 | B15: Questionário de Classificação
A16: US08 | B16: Responder questionário de classificação | C16: RF08 | D16: 2 | E16: 5 | F16: =IF(AND(D16<>"",E16<>""),E16/D16,"") -> 2.5
A17: US09 | B17: Classificar perfil automaticamente | C17: RF09 | D17: 3 | E17: 4 | F17: =IF(AND(D17<>"",E17<>""),E17/D17,"") -> 1.3333333
A18: US10 | B18: Refazer questionário de classificação | C18: RF12 | D18: 2 | E18: 5 | F18: =IF(AND(D18<>"",E18<>""),E18/D18,"") -> 2.5
A19: F04 | B19: Sugestão de Treino Inicial
A20: US11 | B20: Visualizar sugestão de rotina por perfil | C20: RF10 | D20: 3 | E20: 4 | F20: =IF(AND(D20<>"",E20<>""),E20/D20,"") -> 1.3333333
A21: US12 | B21: Recusar sugestão e prosseguir sem rotina | C21: RF11 | D21: 3 | E21: 4 | F21: =IF(AND(D21<>"",E21<>""),E21/D21,"") -> 1.3333333
A22: E03 | B22: Planejamento de Treino
A23: F05 | B23: Gestão de Exercícios
A24: US13 | B24: Cadastrar exercício com nome e grupo muscular | C24: RF13 | D24: 2 | E24: 5 | F24: =IF(AND(D24<>"",E24<>""),E24/D24,"") -> 2.5
A25: US14 | B25: Consultar exercícios por nome ou grupo | C25: RF14 | D25: 3 | E25: 5 | F25: =IF(AND(D25<>"",E25<>""),E25/D25,"") -> 1.6666667
A26: US15 | B26: Editar exercício cadastrado | C26: RF15 | D26: 3 | E26: 5 | F26: =IF(AND(D26<>"",E26<>""),E26/D26,"") -> 1.6666667
A27: US16 | B27: Inativar exercício não utilizado | C27: RF16 | D27: 3 | E27: 4 | F27: =IF(AND(D27<>"",E27<>""),E27/D27,"") -> 1.3333333
A28: F06 | B28: Gestão de Rotinas
A29: US17 | B29: Criar rotina com divisões e parâmetros planejados | C29: RF17 | D29: 3 | E29: 5 | F29: =IF(AND(D29<>"",E29<>""),E29/D29,"") -> 1.6666667
A30: US18 | B30: Consultar rotinas e identificar a ativa | C30: RF18 | D30: 2 | E30: 5 | F30: =IF(AND(D30<>"",E30<>""),E30/D30,"") -> 2.5
A31: US19 | B31: Editar rotina existente | C31: RF19 | D31: 3 | E31: 4 | F31: =IF(AND(D31<>"",E31<>""),E31/D31,"") -> 1.3333333
A32: US20 | B32: Inativar rotina não utilizada | C32: RF20 | D32: 3 | E32: 4 | F32: =IF(AND(D32<>"",E32<>""),E32/D32,"") -> 1.3333333
A33: US21 | B33: Definir rotina como ativa | C33: RF21 | D33: 3 | E33: 5 | F33: =IF(AND(D33<>"",E33<>""),E33/D33,"") -> 1.6666667
A34: E04 | B34: Execução e Registro
A35: F07 | B35: Registro de Sessão
A36: US22 | B36: Registrar sessão de treino com execução real | C36: RF22 | D36: 4 | E36: 4 | F36: =IF(AND(D36<>"",E36<>""),E36/D36,"") -> 1
A37: US23 | B37: Consultar detalhes de uma sessão | C37: RF23 | D37: 3 | E37: 4 | F37: =IF(AND(D37<>"",E37<>""),E37/D37,"") -> 1.3333333
A38: US24 | B38: Editar sessão para corrigir erros | C38: RF24 | D38: 3 | E38: 3 | F38: =IF(AND(D38<>"",E38<>""),E38/D38,"") -> 1
A39: US25 | B39: Excluir sessão registrada | C39: RF25 | D39: 2 | E39: 3 | F39: =IF(AND(D39<>"",E39<>""),E39/D39,"") -> 1.5
A40: E05 | B40: Acompanhamento e Evolução
...

Sheet Daniel
A1: Priorização Individual — Daniel Teles Brito
A2: Complexidade: 1=Muito baixa, 2=Baixa, 3=Média, 4=Alta, 5=Muito alta | Impacto no Usuário: 1=Muito baixo, 2=Baixo, 3=Médio, 4=Alto, 5=Muito alto | Índice = Impacto / Complexidade
A3: Código | B3: Item do Backlog | C3: RF | D3: Complexidade (1-5) | E3: Impacto no Usuário (1-5) | F3: Índice de Prioridade
A4: E01 | B4: Gestão de Conta e Perfil
A5: F01 | B5: Cadastro e Autenticação
A6: US01 | B6: Criar conta com nome, e-mail e senha | C6: RF01 | D6: 1 | E6: 4 | F6: =IF(AND(D6<>"",E6<>""),E6/D6,"") -> 4
A7: US02 | B7: Realizar login com e-mail e senha | C7: RF02 | D7: 1 | E7: 4 | F7: =IF(AND(D7<>"",E7<>""),E7/D7,"") -> 4
A8: US03 | B8: Encerrar acesso autenticado | C8: RF03 | D8: 1 | E8: 4 | F8: =IF(AND(D8<>"",E8<>""),E8/D8,"") -> 4
A9: US04 | B9: Recuperar senha via e-mail | C9: RF04 | D9: 3 | E9: 4 | F9: =IF(AND(D9<>"",E9<>""),E9/D9,"") -> 1.3333333
A10: F02 | B10: Gestão de Perfil
A11: US05 | B11: Visualizar perfil com dados e classificação | C11: RF05 | D11: 2 | E11: 3 | F11: =IF(AND(D11<>"",E11<>""),E11/D11,"") -> 1.5
A12: US06 | B12: Editar nome e senha do perfil | C12: RF06 | D12: 2 | E12: 4 | F12: =IF(AND(D12<>"",E12<>""),E12/D12,"") -> 2
A13: US07 | B13: Excluir conta permanentemente | C13: RF07 | D13: 2 | E13: 2 | F13: =IF(AND(D13<>"",E13<>""),E13/D13,"") -> 1
A14: E02 | B14: Onboarding e Classificação
A15: F03 | B15: Questionário de Classificação
A16: US08 | B16: Responder questionário de classificação | C16: RF08 | D16: 3 | E16: 3 | F16: =IF(AND(D16<>"",E16<>""),E16/D16,"") -> 1
A17: US09 | B17: Classificar perfil automaticamente | C17: RF09 | D17: 5 | E17: 4 | F17: =IF(AND(D17<>"",E17<>""),E17/D17,"") -> 0.8
A18: US10 | B18: Refazer questionário de classificação | C18: RF12 | D18: 4 | E18: 3 | F18: =IF(AND(D18<>"",E18<>""),E18/D18,"") -> 0.75
A19: F04 | B19: Sugestão de Treino Inicial
A20: US11 | B20: Visualizar sugestão de rotina por perfil | C20: RF10 | D20: 5 | E20: 5 | F20: =IF(AND(D20<>"",E20<>""),E20/D20,"") -> 1
A21: US12 | B21: Recusar sugestão e prosseguir sem rotina | C21: RF11 | D21: 2 | E21: 4 | F21: =IF(AND(D21<>"",E21<>""),E21/D21,"") -> 2
A22: E03 | B22: Planejamento de Treino
A23: F05 | B23: Gestão de Exercícios
A24: US13 | B24: Cadastrar exercício com nome e grupo muscular | C24: RF13 | D24: 2 | E24: 3 | F24: =IF(AND(D24<>"",E24<>""),E24/D24,"") -> 1.5
A25: US14 | B25: Consultar exercícios por nome ou grupo | C25: RF14 | D25: 2 | E25: 3 | F25: =IF(AND(D25<>"",E25<>""),E25/D25,"") -> 1.5
A26: US15 | B26: Editar exercício cadastrado | C26: RF15 | D26: 3 | E26: 4 | F26: =IF(AND(D26<>"",E26<>""),E26/D26,"") -> 1.3333333
A27: US16 | B27: Inativar exercício não utilizado | C27: RF16 | D27: 2 | E27: 3 | F27: =IF(AND(D27<>"",E27<>""),E27/D27,"") -> 1.5
A28: F06 | B28: Gestão de Rotinas
A29: US17 | B29: Criar rotina com divisões e parâmetros planejados | C29: RF17 | D29: 5 | E29: 5 | F29: =IF(AND(D29<>"",E29<>""),E29/D29,"") -> 1
A30: US18 | B30: Consultar rotinas e identificar a ativa | C30: RF18 | D30: 2 | E30: 4 | F30: =IF(AND(D30<>"",E30<>""),E30/D30,"") -> 2
A31: US19 | B31: Editar rotina existente | C31: RF19 | D31: 2 | E31: 3 | F31: =IF(AND(D31<>"",E31<>""),E31/D31,"") -> 1.5
A32: US20 | B32: Inativar rotina não utilizada | C32: RF20 | D32: 2 | E32: 2 | F32: =IF(AND(D32<>"",E32<>""),E32/D32,"") -> 1
A33: US21 | B33: Definir rotina como ativa | C33: RF21 | D33: 2 | E33: 3 | F33: =IF(AND(D33<>"",E33<>""),E33/D33,"") -> 1.5
A34: E04 | B34: Execução e Registro
A35: F07 | B35: Registro de Sessão
A36: US22 | B36: Registrar sessão de treino com execução real | C36: RF22 | D36: 3 | E36: 2 | F36: =IF(AND(D36<>"",E36<>""),E36/D36,"") -> 0.66666667
A37: US23 | B37: Consultar detalhes de uma sessão | C37: RF23 | D37: 3 | E37: 4 | F37: =IF(AND(D37<>"",E37<>""),E37/D37,"") -> 1.3333333
A38: US24 | B38: Editar sessão para corrigir erros | C38: RF24 | D38: 2 | E38: 3 | F38: =IF(AND(D38<>"",E38<>""),E38/D38,"") -> 1.5
A39: US25 | B39: Excluir sessão registrada | C39: RF25 | D39: 2 | E39: 3 | F39: =IF(AND(D39<>"",E39<>""),E39/D39,"") -> 1.5
A40: E05 | B40: Acompanhamento e Evolução
...

Sheet Eduardo
A1: Priorização Individual — Eduardo Oliveira Valadares
A2: Complexidade: 1=Muito baixa, 2=Baixa, 3=Média, 4=Alta, 5=Muito alta | Impacto no Usuário: 1=Muito baixo, 2=Baixo, 3=Médio, 4=Alto, 5=Muito alto | Índice = Impacto / Complexidade
A3: Código | B3: Item do Backlog | C3: RF | D3: Complexidade (1-5) | E3: Impacto no Usuário (1-5) | F3: Índice de Prioridade
A4: E01 | B4: Gestão de Conta e Perfil
A5: F01 | B5: Cadastro e Autenticação
A6: US01 | B6: Criar conta com nome, e-mail e senha | C6: RF01 | F6: =IF(AND(D6<>"",E6<>""),E6/D6,"")
A7: US02 | B7: Realizar login com e-mail e senha | C7: RF02 | F7: =IF(AND(D7<>"",E7<>""),E7/D7,"")
A8: US03 | B8: Encerrar acesso autenticado | C8: RF03 | F8: =IF(AND(D8<>"",E8<>""),E8/D8,"")
A9: US04 | B9: Recuperar senha via e-mail | C9: RF04 | F9: =IF(AND(D9<>"",E9<>""),E9/D9,"")
A10: F02 | B10: Gestão de Perfil
A11: US05 | B11: Visualizar perfil com dados e classificação | C11: RF05 | F11: =IF(AND(D11<>"",E11<>""),E11/D11,"")
A12: US06 | B12: Editar nome e senha do perfil | C12: RF06 | F12: =IF(AND(D12<>"",E12<>""),E12/D12,"")
A13: US07 | B13: Excluir conta permanentemente | C13: RF07 | F13: =IF(AND(D13<>"",E13<>""),E13/D13,"")
A14: E02 | B14: Onboarding e Classificação
A15: F03 | B15: Questionário de Classificação
A16: US08 | B16: Responder questionário de classificação | C16: RF08 | F16: =IF(AND(D16<>"",E16<>""),E16/D16,"")
A17: US09 | B17: Classificar perfil automaticamente | C17: RF09 | F17: =IF(AND(D17<>"",E17<>""),E17/D17,"")
A18: US10 | B18: Refazer questionário de classificação | C18: RF12 | F18: =IF(AND(D18<>"",E18<>""),E18/D18,"")
A19: F04 | B19: Sugestão de Treino Inicial
A20: US11 | B20: Visualizar sugestão de rotina por perfil | C20: RF10 | F20: =IF(AND(D20<>"",E20<>""),E20/D20,"")
A21: US12 | B21: Recusar sugestão e prosseguir sem rotina | C21: RF11 | F21: =IF(AND(D21<>"",E21<>""),E21/D21,"")
A22: E03 | B22: Planejamento de Treino
A23: F05 | B23: Gestão de Exercícios
A24: US13 | B24: Cadastrar exercício com nome e grupo muscular | C24: RF13 | F24: =IF(AND(D24<>"",E24<>""),E24/D24,"")
A25: US14 | B25: Consultar exercícios por nome ou grupo | C25: RF14 | F25: =IF(AND(D25<>"",E25<>""),E25/D25,"")
A26: US15 | B26: Editar exercício cadastrado | C26: RF15 | F26: =IF(AND(D26<>"",E26<>""),E26/D26,"")
A27: US16 | B27: Inativar exercício não utilizado | C27: RF16 | F27: =IF(AND(D27<>"",E27<>""),E27/D27,"")
A28: F06 | B28: Gestão de Rotinas
A29: US17 | B29: Criar rotina com divisões e parâmetros planejados | C29: RF17 | F29: =IF(AND(D29<>"",E29<>""),E29/D29,"")
A30: US18 | B30: Consultar rotinas e identificar a ativa | C30: RF18 | F30: =IF(AND(D30<>"",E30<>""),E30/D30,"")
A31: US19 | B31: Editar rotina existente | C31: RF19 | F31: =IF(AND(D31<>"",E31<>""),E31/D31,"")
A32: US20 | B32: Inativar rotina não utilizada | C32: RF20 | F32: =IF(AND(D32<>"",E32<>""),E32/D32,"")
A33: US21 | B33: Definir rotina como ativa | C33: RF21 | F33: =IF(AND(D33<>"",E33<>""),E33/D33,"")
A34: E04 | B34: Execução e Registro
A35: F07 | B35: Registro de Sessão
A36: US22 | B36: Registrar sessão de treino com execução real | C36: RF22 | F36: =IF(AND(D36<>"",E36<>""),E36/D36,"")
A37: US23 | B37: Consultar detalhes de uma sessão | C37: RF23 | F37: =IF(AND(D37<>"",E37<>""),E37/D37,"")
A38: US24 | B38: Editar sessão para corrigir erros | C38: RF24 | F38: =IF(AND(D38<>"",E38<>""),E38/D38,"")
A39: US25 | B39: Excluir sessão registrada | C39: RF25 | F39: =IF(AND(D39<>"",E39<>""),E39/D39,"")
A40: E05 | B40: Acompanhamento e Evolução
...

Sheet Eduardo1
A1: Priorização Individual — Eduardo Silva Waski
A2: Complexidade: 1=Muito baixa, 2=Baixa, 3=Média, 4=Alta, 5=Muito alta | Impacto no Usuário: 1=Muito baixo, 2=Baixo, 3=Médio, 4=Alto, 5=Muito alto | Índice = Impacto / Complexidade
A3: Código | B3: Item do Backlog | C3: RF | D3: Complexidade (1-5) | E3: Impacto no Usuário (1-5) | F3: Índice de Prioridade
A4: E01 | B4: Gestão de Conta e Perfil
A5: F01 | B5: Cadastro e Autenticação
A6: US01 | B6: Criar conta com nome, e-mail e senha | C6: RF01 | D6: 2 | E6: 4 | F6: =IF(AND(D6<>"",E6<>""),E6/D6,"") -> 2
A7: US02 | B7: Realizar login com e-mail e senha | C7: RF02 | D7: 2 | E7: 4 | F7: =IF(AND(D7<>"",E7<>""),E7/D7,"") -> 2
A8: US03 | B8: Encerrar acesso autenticado | C8: RF03 | D8: 1 | E8: 5 | F8: =IF(AND(D8<>"",E8<>""),E8/D8,"") -> 5
A9: US04 | B9: Recuperar senha via e-mail | C9: RF04 | D9: 5 | E9: 5 | F9: =IF(AND(D9<>"",E9<>""),E9/D9,"") -> 1
A10: F02 | B10: Gestão de Perfil
A11: US05 | B11: Visualizar perfil com dados e classificação | C11: RF05 | D11: 2 | E11: 4 | F11: =IF(AND(D11<>"",E11<>""),E11/D11,"") -> 2
A12: US06 | B12: Editar nome e senha do perfil | C12: RF06 | D12: 1 | E12: 5 | F12: =IF(AND(D12<>"",E12<>""),E12/D12,"") -> 5
A13: US07 | B13: Excluir conta permanentemente | C13: RF07 | D13: 1 | E13: 4 | F13: =IF(AND(D13<>"",E13<>""),E13/D13,"") -> 4
A14: E02 | B14: Onboarding e Classificação
A15: F03 | B15: Questionário de Classificação
A16: US08 | B16: Responder questionário de classificação | C16: RF08 | D16: 2 | E16: 5 | F16: =IF(AND(D16<>"",E16<>""),E16/D16,"") -> 2.5
A17: US09 | B17: Classificar perfil automaticamente | C17: RF09 | D17: 2 | E17: 5 | F17: =IF(AND(D17<>"",E17<>""),E17/D17,"") -> 2.5
A18: US10 | B18: Refazer questionário de classificação | C18: RF12 | D18: 2 | E18: 1 | F18: =IF(AND(D18<>"",E18<>""),E18/D18,"") -> 0.5
A19: F04 | B19: Sugestão de Treino Inicial
A20: US11 | B20: Visualizar sugestão de rotina por perfil | C20: RF10 | D20: 3 | E20: 4 | F20: =IF(AND(D20<>"",E20<>""),E20/D20,"") -> 1.3333333
A21: US12 | B21: Recusar sugestão e prosseguir sem rotina | C21: RF11 | D21: 2 | E21: 3 | F21: =IF(AND(D21<>"",E21<>""),E21/D21,"") -> 1.5
A22: E03 | B22: Planejamento de Treino
A23: F05 | B23: Gestão de Exercícios
A24: US13 | B24: Cadastrar exercício com nome e grupo muscular | C24: RF13 | D24: 2 | E24: 4 | F24: =IF(AND(D24<>"",E24<>""),E24/D24,"") -> 2
A25: US14 | B25: Consultar exercícios por nome ou grupo | C25: RF14 | D25: 3 | E25: 4 | F25: =IF(AND(D25<>"",E25<>""),E25/D25,"") -> 1.3333333
A26: US15 | B26: Editar exercício cadastrado | C26: RF15 | D26: 2 | E26: 3 | F26: =IF(AND(D26<>"",E26<>""),E26/D26,"") -> 1.5
A27: US16 | B27: Inativar exercício não utilizado | C27: RF16 | D27: 2 | E27: 2 | F27: =IF(AND(D27<>"",E27<>""),E27/D27,"") -> 1
A28: F06 | B28: Gestão de Rotinas
A29: US17 | B29: Criar rotina com divisões e parâmetros planejados | C29: RF17 | D29: 4 | E29: 5 | F29: =IF(AND(D29<>"",E29<>""),E29/D29,"") -> 1.25
A30: US18 | B30: Consultar rotinas e identificar a ativa | C30: RF18 | D30: 3 | E30: 5 | F30: =IF(AND(D30<>"",E30<>""),E30/D30,"") -> 1.6666667
A31: US19 | B31: Editar rotina existente | C31: RF19 | D31: 3 | E31: 3 | F31: =IF(AND(D31<>"",E31<>""),E31/D31,"") -> 1
A32: US20 | B32: Inativar rotina não utilizada | C32: RF20 | D32: 2 | E32: 4 | F32: =IF(AND(D32<>"",E32<>""),E32/D32,"") -> 2
A33: US21 | B33: Definir rotina como ativa | C33: RF21 | D33: 2 | E33: 4 | F33: =IF(AND(D33<>"",E33<>""),E33/D33,"") -> 2
A34: E04 | B34: Execução e Registro
A35: F07 | B35: Registro de Sessão
A36: US22 | B36: Registrar sessão de treino com execução real | C36: RF22 | D36: 2 | E36: 4 | F36: =IF(AND(D36<>"",E36<>""),E36/D36,"") -> 2
A37: US23 | B37: Consultar detalhes de uma sessão | C37: RF23 | D37: 3 | E37: 5 | F37: =IF(AND(D37<>"",E37<>""),E37/D37,"") -> 1.6666667
A38: US24 | B38: Editar sessão para corrigir erros | C38: RF24 | D38: 3 | E38: 4 | F38: =IF(AND(D38<>"",E38<>""),E38/D38,"") -> 1.3333333
A39: US25 | B39: Excluir sessão registrada | C39: RF25 | D39: 2 | E39: 4 | F39: =IF(AND(D39<>"",E39<>""),E39/D39,"") -> 2
A40: E05 | B40: Acompanhamento e Evolução
...

Sheet Giovanni
A1: Priorização Individual — Giovanni Dornelas Ferreira
A2: Complexidade: 1=Muito baixa, 2=Baixa, 3=Média, 4=Alta, 5=Muito alta | Impacto no Usuário: 1=Muito baixo, 2=Baixo, 3=Médio, 4=Alto, 5=Muito alto | Índice = Impacto / Complexidade
A3: Código | B3: Item do Backlog | C3: RF | D3: Complexidade (1-5) | E3: Impacto no Usuário (1-5) | F3: Índice de Prioridade
A4: E01 | B4: Gestão de Conta e Perfil
A5: F01 | B5: Cadastro e Autenticação
A6: US01 | B6: Criar conta com nome, e-mail e senha | C6: RF01 | D6: 2 | E6: 3 | F6: =IF(AND(D6<>"",E6<>""),E6/D6,"") -> 1.5
A7: US02 | B7: Realizar login com e-mail e senha | C7: RF02 | D7: 1 | E7: 3 | F7: =IF(AND(D7<>"",E7<>""),E7/D7,"") -> 3
A8: US03 | B8: Encerrar acesso autenticado | C8: RF03 | D8: 1 | E8: 3 | F8: =IF(AND(D8<>"",E8<>""),E8/D8,"") -> 3
A9: US04 | B9: Recuperar senha via e-mail | C9: RF04 | D9: 5 | E9: 2 | F9: =IF(AND(D9<>"",E9<>""),E9/D9,"") -> 0.4
A10: F02 | B10: Gestão de Perfil
A11: US05 | B11: Visualizar perfil com dados e classificação | C11: RF05 | D11: 3 | E11: 3 | F11: =IF(AND(D11<>"",E11<>""),E11/D11,"") -> 1
A12: US06 | B12: Editar nome e senha do perfil | C12: RF06 | D12: 3 | E12: 4 | F12: =IF(AND(D12<>"",E12<>""),E12/D12,"") -> 1.3333333
A13: US07 | B13: Excluir conta permanentemente | C13: RF07 | D13: 1 | E13: 3 | F13: =IF(AND(D13<>"",E13<>""),E13/D13,"") -> 3
A14: E02 | B14: Onboarding e Classificação
A15: F03 | B15: Questionário de Classificação
A16: US08 | B16: Responder questionário de classificação | C16: RF08 | D16: 2 | E16: 4 | F16: =IF(AND(D16<>"",E16<>""),E16/D16,"") -> 2
A17: US09 | B17: Classificar perfil automaticamente | C17: RF09 | D17: 3 | E17: 4 | F17: =IF(AND(D17<>"",E17<>""),E17/D17,"") -> 1.3333333
A18: US10 | B18: Refazer questionário de classificação | C18: RF12 | D18: 2 | E18: 4 | F18: =IF(AND(D18<>"",E18<>""),E18/D18,"") -> 2
A19: F04 | B19: Sugestão de Treino Inicial
A20: US11 | B20: Visualizar sugestão de rotina por perfil | C20: RF10 | D20: 3 | E20: 4 | F20: =IF(AND(D20<>"",E20<>""),E20/D20,"") -> 1.3333333
A21: US12 | B21: Recusar sugestão e prosseguir sem rotina | C21: RF11 | D21: 2 | E21: 3 | F21: =IF(AND(D21<>"",E21<>""),E21/D21,"") -> 1.5
A22: E03 | B22: Planejamento de Treino
A23: F05 | B23: Gestão de Exercícios
A24: US13 | B24: Cadastrar exercício com nome e grupo muscular | C24: RF13 | D24: 2 | E24: 5 | F24: =IF(AND(D24<>"",E24<>""),E24/D24,"") -> 2.5
A25: US14 | B25: Consultar exercícios por nome ou grupo | C25: RF14 | D25: 2 | E25: 4 | F25: =IF(AND(D25<>"",E25<>""),E25/D25,"") -> 2
A26: US15 | B26: Editar exercício cadastrado | C26: RF15 | D26: 2 | E26: 5 | F26: =IF(AND(D26<>"",E26<>""),E26/D26,"") -> 2.5
A27: US16 | B27: Inativar exercício não utilizado | C27: RF16 | D27: 2 | E27: 4 | F27: =IF(AND(D27<>"",E27<>""),E27/D27,"") -> 2
A28: F06 | B28: Gestão de Rotinas
A29: US17 | B29: Criar rotina com divisões e parâmetros planejados | C29: RF17 | D29: 3 | E29: 5 | F29: =IF(AND(D29<>"",E29<>""),E29/D29,"") -> 1.6666667
A30: US18 | B30: Consultar rotinas e identificar a ativa | C30: RF18 | D30: 2 | E30: 5 | F30: =IF(AND(D30<>"",E30<>""),E30/D30,"") -> 2.5
A31: US19 | B31: Editar rotina existente | C31: RF19 | D31: 3 | E31: 5 | F31: =IF(AND(D31<>"",E31<>""),E31/D31,"") -> 1.6666667
A32: US20 | B32: Inativar rotina não utilizada | C32: RF20 | D32: 2 | E32: 4 | F32: =IF(AND(D32<>"",E32<>""),E32/D32,"") -> 2
A33: US21 | B33: Definir rotina como ativa | C33: RF21 | D33: 2 | E33: 5 | F33: =IF(AND(D33<>"",E33<>""),E33/D33,"") -> 2.5
A34: E04 | B34: Execução e Registro
A35: F07 | B35: Registro de Sessão
A36: US22 | B36: Registrar sessão de treino com execução real | C36: RF22 | D36: 4 | E36: 3 | F36: =IF(AND(D36<>"",E36<>""),E36/D36,"") -> 0.75
A37: US23 | B37: Consultar detalhes de uma sessão | C37: RF23 | D37: 2 | E37: 4 | F37: =IF(AND(D37<>"",E37<>""),E37/D37,"") -> 2
A38: US24 | B38: Editar sessão para corrigir erros | C38: RF24 | D38: 2 | E38: 4 | F38: =IF(AND(D38<>"",E38<>""),E38/D38,"") -> 2
A39: US25 | B39: Excluir sessão registrada | C39: RF25 | D39: 1 | E39: 4 | F39: =IF(AND(D39<>"",E39<>""),E39/D39,"") -> 4
A40: E05 | B40: Acompanhamento e Evolução
...

Sheet João
A1: Priorização Individual — João Maurício Pilla Nascimento
A2: Complexidade: 1=Muito baixa, 2=Baixa, 3=Média, 4=Alta, 5=Muito alta | Impacto no Usuário: 1=Muito baixo, 2=Baixo, 3=Médio, 4=Alto, 5=Muito alto | Índice = Impacto / Complexidade
A3: Código | B3: Item do Backlog | C3: RF | D3: Complexidade (1-5) | E3: Impacto no Usuário (1-5) | F3: Índice de Prioridade
A4: E01 | B4: Gestão de Conta e Perfil
A5: F01 | B5: Cadastro e Autenticação
A6: US01 | B6: Criar conta com nome, e-mail e senha | C6: RF01 | D6: 2 | E6: 5 | F6: =IF(AND(D6<>"",E6<>""),E6/D6,"") -> 2.5
A7: US02 | B7: Realizar login com e-mail e senha | C7: RF02 | D7: 2 | E7: 5 | F7: =IF(AND(D7<>"",E7<>""),E7/D7,"") -> 2.5
A8: US03 | B8: Encerrar acesso autenticado | C8: RF03 | D8: 2 | E8: 4 | F8: =IF(AND(D8<>"",E8<>""),E8/D8,"") -> 2
A9: US04 | B9: Recuperar senha via e-mail | C9: RF04 | D9: 4 | E9: 3 | F9: =IF(AND(D9<>"",E9<>""),E9/D9,"") -> 0.75
A10: F02 | B10: Gestão de Perfil
A11: US05 | B11: Visualizar perfil com dados e classificação | C11: RF05 | D11: 2 | E11: 5 | F11: =IF(AND(D11<>"",E11<>""),E11/D11,"") -> 2.5
A12: US06 | B12: Editar nome e senha do perfil | C12: RF06 | D12: 2 | E12: 4 | F12: =IF(AND(D12<>"",E12<>""),E12/D12,"") -> 2
A13: US07 | B13: Excluir conta permanentemente | C13: RF07 | D13: 1 | E13: 3 | F13: =IF(AND(D13<>"",E13<>""),E13/D13,"") -> 3
A14: E02 | B14: Onboarding e Classificação
A15: F03 | B15: Questionário de Classificação
A16: US08 | B16: Responder questionário de classificação | C16: RF08 | D16: 2 | E16: 4 | F16: =IF(AND(D16<>"",E16<>""),E16/D16,"") -> 2
A17: US09 | B17: Classificar perfil automaticamente | C17: RF09 | D17: 3 | E17: 4 | F17: =IF(AND(D17<>"",E17<>""),E17/D17,"") -> 1.3333333
A18: US10 | B18: Refazer questionário de classificação | C18: RF12 | D18: 2 | E18: 3 | F18: =IF(AND(D18<>"",E18<>""),E18/D18,"") -> 1.5
A19: F04 | B19: Sugestão de Treino Inicial
A20: US11 | B20: Visualizar sugestão de rotina por perfil | C20: RF10 | D20: 2 | E20: 5 | F20: =IF(AND(D20<>"",E20<>""),E20/D20,"") -> 2.5
A21: US12 | B21: Recusar sugestão e prosseguir sem rotina | C21: RF11 | D21: 1 | E21: 4 | F21: =IF(AND(D21<>"",E21<>""),E21/D21,"") -> 4
A22: E03 | B22: Planejamento de Treino
A23: F05 | B23: Gestão de Exercícios
A24: US13 | B24: Cadastrar exercício com nome e grupo muscular | C24: RF13 | D24: 3 | E24: 5 | F24: =IF(AND(D24<>"",E24<>""),E24/D24,"") -> 1.6666667
A25: US14 | B25: Consultar exercícios por nome ou grupo | C25: RF14 | D25: 2 | E25: 4 | F25: =IF(AND(D25<>"",E25<>""),E25/D25,"") -> 2
A26: US15 | B26: Editar exercício cadastrado | C26: RF15 | D26: 3 | E26: 3 | F26: =IF(AND(D26<>"",E26<>""),E26/D26,"") -> 1
A27: US16 | B27: Inativar exercício não utilizado | C27: RF16 | D27: 2 | E27: 3 | F27: =IF(AND(D27<>"",E27<>""),E27/D27,"") -> 1.5
A28: F06 | B28: Gestão de Rotinas
A29: US17 | B29: Criar rotina com divisões e parâmetros planejados | C29: RF17 | D29: 4 | E29: 5 | F29: =IF(AND(D29<>"",E29<>""),E29/D29,"") -> 1.25
A30: US18 | B30: Consultar rotinas e identificar a ativa | C30: RF18 | D30: 3 | E30: 5 | F30: =IF(AND(D30<>"",E30<>""),E30/D30,"") -> 1.6666667
A31: US19 | B31: Editar rotina existente | C31: RF19 | D31: 3 | E31: 4 | F31: =IF(AND(D31<>"",E31<>""),E31/D31,"") -> 1.3333333
A32: US20 | B32: Inativar rotina não utilizada | C32: RF20 | D32: 2 | E32: 3 | F32: =IF(AND(D32<>"",E32<>""),E32/D32,"") -> 1.5
A33: US21 | B33: Definir rotina como ativa | C33: RF21 | D33: 2 | E33: 3 | F33: =IF(AND(D33<>"",E33<>""),E33/D33,"") -> 1.5
A34: E04 | B34: Execução e Registro
A35: F07 | B35: Registro de Sessão
A36: US22 | B36: Registrar sessão de treino com execução real | C36: RF22 | D36: 3 | E36: 5 | F36: =IF(AND(D36<>"",E36<>""),E36/D36,"") -> 1.6666667
A37: US23 | B37: Consultar detalhes de uma sessão | C37: RF23 | D37: 2 | E37: 5 | F37: =IF(AND(D37<>"",E37<>""),E37/D37,"") -> 2.5
A38: US24 | B38: Editar sessão para corrigir erros | C38: RF24 | D38: 3 | E38: 3 | F38: =IF(AND(D38<>"",E38<>""),E38/D38,"") -> 1
A39: US25 | B39: Excluir sessão registrada | C39: RF25 | D39: 1 | E39: 3 | F39: =IF(AND(D39<>"",E39<>""),E39/D39,"") -> 3
A40: E05 | B40: Acompanhamento e Evolução
...

Sheet José
A1: Priorização Individual — José Victor Gabriel Menezes da Costa
A2: Complexidade: 1=Muito baixa, 2=Baixa, 3=Média, 4=Alta, 5=Muito alta | Impacto no Usuário: 1=Muito baixo, 2=Baixo, 3=Médio, 4=Alto, 5=Muito alto | Índice = Impacto / Complexidade
A3: Código | B3: Item do Backlog | C3: RF | D3: Complexidade (1-5) | E3: Impacto no Usuário (1-5) | F3: Índice de Prioridade
A4: E01 | B4: Gestão de Conta e Perfil
A5: F01 | B5: Cadastro e Autenticação
A6: US01 | B6: Criar conta com nome, e-mail e senha | C6: RF01 | D6: 1 | E6: 2 | F6: =IF(AND(D6<>"",E6<>""),E6/D6,"") -> 2
A7: US02 | B7: Realizar login com e-mail e senha | C7: RF02 | D7: 1 | E7: 3 | F7: =IF(AND(D7<>"",E7<>""),E7/D7,"") -> 3
A8: US03 | B8: Encerrar acesso autenticado | C8: RF03 | D8: 1 | E8: 2 | F8: =IF(AND(D8<>"",E8<>""),E8/D8,"") -> 2
A9: US04 | B9: Recuperar senha via e-mail | C9: RF04 | D9: 5 | E9: 2 | F9: =IF(AND(D9<>"",E9<>""),E9/D9,"") -> 0.4
A10: F02 | B10: Gestão de Perfil
A11: US05 | B11: Visualizar perfil com dados e classificação | C11: RF05 | D11: 3 | E11: 3 | F11: =IF(AND(D11<>"",E11<>""),E11/D11,"") -> 1
A12: US06 | B12: Editar nome e senha do perfil | C12: RF06 | D12: 1 | E12: 2 | F12: =IF(AND(D12<>"",E12<>""),E12/D12,"") -> 2
A13: US07 | B13: Excluir conta permanentemente | C13: RF07 | D13: 1 | E13: 3 | F13: =IF(AND(D13<>"",E13<>""),E13/D13,"") -> 3
A14: E02 | B14: Onboarding e Classificação
A15: F03 | B15: Questionário de Classificação
A16: US08 | B16: Responder questionário de classificação | C16: RF08 | D16: 2 | E16: 3 | F16: =IF(AND(D16<>"",E16<>""),E16/D16,"") -> 1.5
A17: US09 | B17: Classificar perfil automaticamente | C17: RF09 | D17: 2 | E17: 4 | F17: =IF(AND(D17<>"",E17<>""),E17/D17,"") -> 2
A18: US10 | B18: Refazer questionário de classificação | C18: RF12 | D18: 2 | E18: 4 | F18: =IF(AND(D18<>"",E18<>""),E18/D18,"") -> 2
A19: F04 | B19: Sugestão de Treino Inicial
A20: US11 | B20: Visualizar sugestão de rotina por perfil | C20: RF10 | D20: 3 | E20: 4 | F20: =IF(AND(D20<>"",E20<>""),E20/D20,"") -> 1.3333333
A21: US12 | B21: Recusar sugestão e prosseguir sem rotina | C21: RF11 | D21: 1 | E21: 4 | F21: =IF(AND(D21<>"",E21<>""),E21/D21,"") -> 4
A22: E03 | B22: Planejamento de Treino
A23: F05 | B23: Gestão de Exercícios
A24: US13 | B24: Cadastrar exercício com nome e grupo muscular | C24: RF13 | D24: 2 | E24: 5 | F24: =IF(AND(D24<>"",E24<>""),E24/D24,"") -> 2.5
A25: US14 | B25: Consultar exercícios por nome ou grupo | C25: RF14 | D25: 1 | E25: 4 | F25: =IF(AND(D25<>"",E25<>""),E25/D25,"") -> 4
A26: US15 | B26: Editar exercício cadastrado | C26: RF15 | D26: 2 | E26: 4 | F26: =IF(AND(D26<>"",E26<>""),E26/D26,"") -> 2
A27: US16 | B27: Inativar exercício não utilizado | C27: RF16 | D27: 1 | E27: 3 | F27: =IF(AND(D27<>"",E27<>""),E27/D27,"") -> 3
A28: F06 | B28: Gestão de Rotinas
A29: US17 | B29: Criar rotina com divisões e parâmetros planejados | C29: RF17 | D29: 3 | E29: 5 | F29: =IF(AND(D29<>"",E29<>""),E29/D29,"") -> 1.6666667
A30: US18 | B30: Consultar rotinas e identificar a ativa | C30: RF18 | D30: 2 | E30: 5 | F30: =IF(AND(D30<>"",E30<>""),E30/D30,"") -> 2.5
A31: US19 | B31: Editar rotina existente | C31: RF19 | D31: 3 | E31: 5 | F31: =IF(AND(D31<>"",E31<>""),E31/D31,"") -> 1.6666667
A32: US20 | B32: Inativar rotina não utilizada | C32: RF20 | D32: 1 | E32: 4 | F32: =IF(AND(D32<>"",E32<>""),E32/D32,"") -> 4
A33: US21 | B33: Definir rotina como ativa | C33: RF21 | D33: 1 | E33: 4 | F33: =IF(AND(D33<>"",E33<>""),E33/D33,"") -> 4
A34: E04 | B34: Execução e Registro
A35: F07 | B35: Registro de Sessão
A36: US22 | B36: Registrar sessão de treino com execução real | C36: RF22 | D36: 4 | E36: 3 | F36: =IF(AND(D36<>"",E36<>""),E36/D36,"") -> 0.75
A37: US23 | B37: Consultar detalhes de uma sessão | C37: RF23 | D37: 3 | E37: 3 | F37: =IF(AND(D37<>"",E37<>""),E37/D37,"") -> 1
A38: US24 | B38: Editar sessão para corrigir erros | C38: RF24 | D38: 3 | E38: 2 | F38: =IF(AND(D38<>"",E38<>""),E38/D38,"") -> 0.66666667
A39: US25 | B39: Excluir sessão registrada | C39: RF25 | D39: 1 | E39: 3 | F39: =IF(AND(D39<>"",E39<>""),E39/D39,"") -> 3
A40: E05 | B40: Acompanhamento e Evolução
...

Sheet Lucas
A1: Priorização Individual — Lucas Gabriel da Silva Antunes
A2: Complexidade: 1=Muito baixa, 2=Baixa, 3=Média, 4=Alta, 5=Muito alta | Impacto no Usuário: 1=Muito baixo, 2=Baixo, 3=Médio, 4=Alto, 5=Muito alto | Índice = Impacto / Complexidade
A3: Código | B3: Item do Backlog | C3: RF | D3: Complexidade (1-5) | E3: Impacto no Usuário (1-5) | F3: Índice de Prioridade
A4: E01 | B4: Gestão de Conta e Perfil
A5: F01 | B5: Cadastro e Autenticação
A6: US01 | B6: Criar conta com nome, e-mail e senha | C6: RF01 | D6: 1 | E6: 5 | F6: =IF(AND(D6<>"",E6<>""),E6/D6,"") -> 5
A7: US02 | B7: Realizar login com e-mail e senha | C7: RF02 | D7: 1 | E7: 5 | F7: =IF(AND(D7<>"",E7<>""),E7/D7,"") -> 5
A8: US03 | B8: Encerrar acesso autenticado | C8: RF03 | D8: 1 | E8: 5 | F8: =IF(AND(D8<>"",E8<>""),E8/D8,"") -> 5
A9: US04 | B9: Recuperar senha via e-mail | C9: RF04 | D9: 3 | E9: 5 | F9: =IF(AND(D9<>"",E9<>""),E9/D9,"") -> 1.6666667
A10: F02 | B10: Gestão de Perfil
A11: US05 | B11: Visualizar perfil com dados e classificação | C11: RF05 | D11: 3 | E11: 3 | F11: =IF(AND(D11<>"",E11<>""),E11/D11,"") -> 1
A12: US06 | B12: Editar nome e senha do perfil | C12: RF06 | D12: 1 | E12: 3 | F12: =IF(AND(D12<>"",E12<>""),E12/D12,"") -> 3
A13: US07 | B13: Excluir conta permanentemente | C13: RF07 | D13: 2 | E13: 3 | F13: =IF(AND(D13<>"",E13<>""),E13/D13,"") -> 1.5
A14: E02 | B14: Onboarding e Classificação
A15: F03 | B15: Questionário de Classificação
A16: US08 | B16: Responder questionário de classificação | C16: RF08 | D16: 2 | E16: 4 | F16: =IF(AND(D16<>"",E16<>""),E16/D16,"") -> 2
A17: US09 | B17: Classificar perfil automaticamente | C17: RF09 | D17: 3 | E17: 4 | F17: =IF(AND(D17<>"",E17<>""),E17/D17,"") -> 1.3333333
A18: US10 | B18: Refazer questionário de classificação | C18: RF12 | D18: 3 | E18: 2 | F18: =IF(AND(D18<>"",E18<>""),E18/D18,"") -> 0.66666667
A19: F04 | B19: Sugestão de Treino Inicial
A20: US11 | B20: Visualizar sugestão de rotina por perfil | C20: RF10 | D20: 2 | E20: 4 | F20: =IF(AND(D20<>"",E20<>""),E20/D20,"") -> 2
A21: US12 | B21: Recusar sugestão e prosseguir sem rotina | C21: RF11 | D21: 1 | E21: 3 | F21: =IF(AND(D21<>"",E21<>""),E21/D21,"") -> 3
A22: E03 | B22: Planejamento de Treino
A23: F05 | B23: Gestão de Exercícios
A24: US13 | B24: Cadastrar exercício com nome e grupo muscular | C24: RF13 | D24: 1 | E24: 5 | F24: =IF(AND(D24<>"",E24<>""),E24/D24,"") -> 5
A25: US14 | B25: Consultar exercícios por nome ou grupo | C25: RF14 | D25: 1 | E25: 5 | F25: =IF(AND(D25<>"",E25<>""),E25/D25,"") -> 5
A26: US15 | B26: Editar exercício cadastrado | C26: RF15 | D26: 1 | E26: 5 | F26: =IF(AND(D26<>"",E26<>""),E26/D26,"") -> 5
A27: US16 | B27: Inativar exercício não utilizado | C27: RF16 | D27: 1 | E27: 5 | F27: =IF(AND(D27<>"",E27<>""),E27/D27,"") -> 5
A28: F06 | B28: Gestão de Rotinas
A29: US17 | B29: Criar rotina com divisões e parâmetros planejados | C29: RF17 | D29: 1 | E29: 5 | F29: =IF(AND(D29<>"",E29<>""),E29/D29,"") -> 5
A30: US18 | B30: Consultar rotinas e identificar a ativa | C30: RF18 | D30: 1 | E30: 5 | F30: =IF(AND(D30<>"",E30<>""),E30/D30,"") -> 5
A31: US19 | B31: Editar rotina existente | C31: RF19 | D31: 1 | E31: 5 | F31: =IF(AND(D31<>"",E31<>""),E31/D31,"") -> 5
A32: US20 | B32: Inativar rotina não utilizada | C32: RF20 | D32: 1 | E32: 5 | F32: =IF(AND(D32<>"",E32<>""),E32/D32,"") -> 5
A33: US21 | B33: Definir rotina como ativa | C33: RF21 | D33: 1 | E33: 5 | F33: =IF(AND(D33<>"",E33<>""),E33/D33,"") -> 5
A34: E04 | B34: Execução e Registro
A35: F07 | B35: Registro de Sessão
A36: US22 | B36: Registrar sessão de treino com execução real | C36: RF22 | D36: 1 | E36: 5 | F36: =IF(AND(D36<>"",E36<>""),E36/D36,"") -> 5
A37: US23 | B37: Consultar detalhes de uma sessão | C37: RF23 | D37: 1 | E37: 5 | F37: =IF(AND(D37<>"",E37<>""),E37/D37,"") -> 5
A38: US24 | B38: Editar sessão para corrigir erros | C38: RF24 | D38: 1 | E38: 5 | F38: =IF(AND(D38<>"",E38<>""),E38/D38,"") -> 5
A39: US25 | B39: Excluir sessão registrada | C39: RF25 | D39: 1 | E39: 5 | F39: =IF(AND(D39<>"",E39<>""),E39/D39,"") -> 5
A40: E05 | B40: Acompanhamento e Evolução
...

Sheet Samuel
A1: Priorização Individual — Samuel Nogueira Caetano
A2: Complexidade: 1=Muito baixa, 2=Baixa, 3=Média, 4=Alta, 5=Muito alta | Impacto no Usuário: 1=Muito baixo, 2=Baixo, 3=Médio, 4=Alto, 5=Muito alto | Índice = Impacto / Complexidade
A3: Código | B3: Item do Backlog | C3: RF | D3: Complexidade (1-5) | E3: Impacto no Usuário (1-5) | F3: Índice de Prioridade
A4: E01 | B4: Gestão de Conta e Perfil
A5: F01 | B5: Cadastro e Autenticação
A6: US01 | B6: Criar conta com nome, e-mail e senha | C6: RF01 | F6: =IF(AND(D6<>"",E6<>""),E6/D6,"")
A7: US02 | B7: Realizar login com e-mail e senha | C7: RF02 | F7: =IF(AND(D7<>"",E7<>""),E7/D7,"")
A8: US03 | B8: Encerrar acesso autenticado | C8: RF03 | F8: =IF(AND(D8<>"",E8<>""),E8/D8,"")
A9: US04 | B9: Recuperar senha via e-mail | C9: RF04 | F9: =IF(AND(D9<>"",E9<>""),E9/D9,"")
A10: F02 | B10: Gestão de Perfil
A11: US05 | B11: Visualizar perfil com dados e classificação | C11: RF05 | F11: =IF(AND(D11<>"",E11<>""),E11/D11,"")
A12: US06 | B12: Editar nome e senha do perfil | C12: RF06 | F12: =IF(AND(D12<>"",E12<>""),E12/D12,"")
A13: US07 | B13: Excluir conta permanentemente | C13: RF07 | F13: =IF(AND(D13<>"",E13<>""),E13/D13,"")
A14: E02 | B14: Onboarding e Classificação
A15: F03 | B15: Questionário de Classificação
A16: US08 | B16: Responder questionário de classificação | C16: RF08 | F16: =IF(AND(D16<>"",E16<>""),E16/D16,"")
A17: US09 | B17: Classificar perfil automaticamente | C17: RF09 | F17: =IF(AND(D17<>"",E17<>""),E17/D17,"")
A18: US10 | B18: Refazer questionário de classificação | C18: RF12 | F18: =IF(AND(D18<>"",E18<>""),E18/D18,"")
A19: F04 | B19: Sugestão de Treino Inicial
A20: US11 | B20: Visualizar sugestão de rotina por perfil | C20: RF10 | F20: =IF(AND(D20<>"",E20<>""),E20/D20,"")
A21: US12 | B21: Recusar sugestão e prosseguir sem rotina | C21: RF11 | F21: =IF(AND(D21<>"",E21<>""),E21/D21,"")
A22: E03 | B22: Planejamento de Treino
A23: F05 | B23: Gestão de Exercícios
A24: US13 | B24: Cadastrar exercício com nome e grupo muscular | C24: RF13 | F24: =IF(AND(D24<>"",E24<>""),E24/D24,"")
A25: US14 | B25: Consultar exercícios por nome ou grupo | C25: RF14 | F25: =IF(AND(D25<>"",E25<>""),E25/D25,"")
A26: US15 | B26: Editar exercício cadastrado | C26: RF15 | F26: =IF(AND(D26<>"",E26<>""),E26/D26,"")
A27: US16 | B27: Inativar exercício não utilizado | C27: RF16 | F27: =IF(AND(D27<>"",E27<>""),E27/D27,"")
A28: F06 | B28: Gestão de Rotinas
A29: US17 | B29: Criar rotina com divisões e parâmetros planejados | C29: RF17 | F29: =IF(AND(D29<>"",E29<>""),E29/D29,"")
A30: US18 | B30: Consultar rotinas e identificar a ativa | C30: RF18 | F30: =IF(AND(D30<>"",E30<>""),E30/D30,"")
A31: US19 | B31: Editar rotina existente | C31: RF19 | F31: =IF(AND(D31<>"",E31<>""),E31/D31,"")
A32: US20 | B32: Inativar rotina não utilizada | C32: RF20 | F32: =IF(AND(D32<>"",E32<>""),E32/D32,"")
A33: US21 | B33: Definir rotina como ativa | C33: RF21 | F33: =IF(AND(D33<>"",E33<>""),E33/D33,"")
A34: E04 | B34: Execução e Registro
A35: F07 | B35: Registro de Sessão
A36: US22 | B36: Registrar sessão de treino com execução real | C36: RF22 | F36: =IF(AND(D36<>"",E36<>""),E36/D36,"")
A37: US23 | B37: Consultar detalhes de uma sessão | C37: RF23 | F37: =IF(AND(D37<>"",E37<>""),E37/D37,"")
A38: US24 | B38: Editar sessão para corrigir erros | C38: RF24 | F38: =IF(AND(D38<>"",E38<>""),E38/D38,"")
A39: US25 | B39: Excluir sessão registrada | C39: RF25 | F39: =IF(AND(D39<>"",E39<>""),E39/D39,"")
A40: E05 | B40: Acompanhamento e Evolução
...

Sheet Mateus
A1: Priorização Individual — Mateus Santos Negrini
A2: Complexidade: 1=Muito baixa, 2=Baixa, 3=Média, 4=Alta, 5=Muito alta | Impacto no Usuário: 1=Muito baixo, 2=Baixo, 3=Médio, 4=Alto, 5=Muito alto | Índice = Impacto / Complexidade
A3: Código | B3: Item do Backlog | C3: RF | D3: Complexidade (1-5) | E3: Impacto no Usuário (1-5) | F3: Índice de Prioridade
A4: E01 | B4: Gestão de Conta e Perfil
A5: F01 | B5: Cadastro e Autenticação
A6: US01 | B6: Criar conta com nome, e-mail e senha | C6: RF01 | F6: =IF(AND(D6<>"",E6<>""),E6/D6,"")
A7: US02 | B7: Realizar login com e-mail e senha | C7: RF02 | F7: =IF(AND(D7<>"",E7<>""),E7/D7,"")
A8: US03 | B8: Encerrar acesso autenticado | C8: RF03 | F8: =IF(AND(D8<>"",E8<>""),E8/D8,"")
A9: US04 | B9: Recuperar senha via e-mail | C9: RF04 | F9: =IF(AND(D9<>"",E9<>""),E9/D9,"")
A10: F02 | B10: Gestão de Perfil
A11: US05 | B11: Visualizar perfil com dados e classificação | C11: RF05 | F11: =IF(AND(D11<>"",E11<>""),E11/D11,"")
A12: US06 | B12: Editar nome e senha do perfil | C12: RF06 | F12: =IF(AND(D12<>"",E12<>""),E12/D12,"")
A13: US07 | B13: Excluir conta permanentemente | C13: RF07 | F13: =IF(AND(D13<>"",E13<>""),E13/D13,"")
A14: E02 | B14: Onboarding e Classificação
A15: F03 | B15: Questionário de Classificação
A16: US08 | B16: Responder questionário de classificação | C16: RF08 | F16: =IF(AND(D16<>"",E16<>""),E16/D16,"")
A17: US09 | B17: Classificar perfil automaticamente | C17: RF09 | F17: =IF(AND(D17<>"",E17<>""),E17/D17,"")
A18: US10 | B18: Refazer questionário de classificação | C18: RF12 | F18: =IF(AND(D18<>"",E18<>""),E18/D18,"")
A19: F04 | B19: Sugestão de Treino Inicial
A20: US11 | B20: Visualizar sugestão de rotina por perfil | C20: RF10 | F20: =IF(AND(D20<>"",E20<>""),E20/D20,"")
A21: US12 | B21: Recusar sugestão e prosseguir sem rotina | C21: RF11 | F21: =IF(AND(D21<>"",E21<>""),E21/D21,"")
A22: E03 | B22: Planejamento de Treino
A23: F05 | B23: Gestão de Exercícios
A24: US13 | B24: Cadastrar exercício com nome e grupo muscular | C24: RF13 | F24: =IF(AND(D24<>"",E24<>""),E24/D24,"")
A25: US14 | B25: Consultar exercícios por nome ou grupo | C25: RF14 | F25: =IF(AND(D25<>"",E25<>""),E25/D25,"")
A26: US15 | B26: Editar exercício cadastrado | C26: RF15 | F26: =IF(AND(D26<>"",E26<>""),E26/D26,"")
A27: US16 | B27: Inativar exercício não utilizado | C27: RF16 | F27: =IF(AND(D27<>"",E27<>""),E27/D27,"")
A28: F06 | B28: Gestão de Rotinas
A29: US17 | B29: Criar rotina com divisões e parâmetros planejados | C29: RF17 | F29: =IF(AND(D29<>"",E29<>""),E29/D29,"")
A30: US18 | B30: Consultar rotinas e identificar a ativa | C30: RF18 | F30: =IF(AND(D30<>"",E30<>""),E30/D30,"")
A31: US19 | B31: Editar rotina existente | C31: RF19 | F31: =IF(AND(D31<>"",E31<>""),E31/D31,"")
A32: US20 | B32: Inativar rotina não utilizada | C32: RF20 | F32: =IF(AND(D32<>"",E32<>""),E32/D32,"")
A33: US21 | B33: Definir rotina como ativa | C33: RF21 | F33: =IF(AND(D33<>"",E33<>""),E33/D33,"")
A34: E04 | B34: Execução e Registro
A35: F07 | B35: Registro de Sessão
A36: US22 | B36: Registrar sessão de treino com execução real | C36: RF22 | F36: =IF(AND(D36<>"",E36<>""),E36/D36,"")
A37: US23 | B37: Consultar detalhes de uma sessão | C37: RF23 | F37: =IF(AND(D37<>"",E37<>""),E37/D37,"")
A38: US24 | B38: Editar sessão para corrigir erros | C38: RF24 | F38: =IF(AND(D38<>"",E38<>""),E38/D38,"")
A39: US25 | B39: Excluir sessão registrada | C39: RF25 | F39: =IF(AND(D39<>"",E39<>""),E39/D39,"")
A40: E05 | B40: Acompanhamento e Evolução
...
